Traceback (most recent call last):
  File "C:\Users\eeu227\AppData\Local\Continuum\anaconda3\envs\jbook_env\lib\site-packages\jupyter_cache\executors\utils.py", line 56, in single_nb_execution
    record_timing=False,
  File "C:\Users\eeu227\AppData\Local\Continuum\anaconda3\envs\jbook_env\lib\site-packages\nbclient\client.py", line 1093, in execute
    return NotebookClient(nb=nb, resources=resources, km=km, **kwargs).execute()
  File "C:\Users\eeu227\AppData\Local\Continuum\anaconda3\envs\jbook_env\lib\site-packages\nbclient\util.py", line 84, in wrapped
    return just_run(coro(*args, **kwargs))
  File "C:\Users\eeu227\AppData\Local\Continuum\anaconda3\envs\jbook_env\lib\site-packages\nbclient\util.py", line 62, in just_run
    return loop.run_until_complete(coro)
  File "C:\Users\eeu227\AppData\Local\Continuum\anaconda3\envs\jbook_env\lib\asyncio\base_events.py", line 587, in run_until_complete
    return future.result()
  File "C:\Users\eeu227\AppData\Local\Continuum\anaconda3\envs\jbook_env\lib\site-packages\nbclient\client.py", line 560, in async_execute
    cell, index, execution_count=self.code_cells_executed + 1
  File "C:\Users\eeu227\AppData\Local\Continuum\anaconda3\envs\jbook_env\lib\site-packages\nbclient\client.py", line 854, in async_execute_cell
    self._check_raise_for_error(cell, exec_reply)
  File "C:\Users\eeu227\AppData\Local\Continuum\anaconda3\envs\jbook_env\lib\site-packages\nbclient\client.py", line 756, in _check_raise_for_error
    raise CellExecutionError.from_cell_and_msg(cell, exec_reply_content)
nbclient.exceptions.CellExecutionError: An error occurred while executing the following cell:
------------------
from statsmodels.tsa.arima_process import arma_acovf
from scipy.linalg import toeplitz
import numpy as np

acov1 = arma_acovf(ar=[1, -.4], ma=[1], nobs=10, sigma2=1)
Sigma1 = toeplitz(acov1)
acov2 = arma_acovf(ar=[1,], ma=[1, .3], nobs=10, sigma2=1)
Sigma2 = toeplitz(acov2)


print(np.linalg.inv(Sigma1[:3][:,:3]).round(4))
print(np.linalg.inv(Sigma2[:3][:,:3]).round(4))
------------------

[1;31m---------------------------------------------------------------------------[0m
[1;31mModuleNotFoundError[0m                       Traceback (most recent call last)
[1;32mC:\Users\eeu227\AppData\Local\Temp/ipykernel_51520/1071994973.py[0m in [0;36m<module>[1;34m[0m
[1;32m----> 1[1;33m [1;32mfrom[0m [0mstatsmodels[0m[1;33m.[0m[0mtsa[0m[1;33m.[0m[0marima_process[0m [1;32mimport[0m [0marma_acovf[0m[1;33m[0m[1;33m[0m[0m
[0m[0;32m      2[0m [1;32mfrom[0m [0mscipy[0m[1;33m.[0m[0mlinalg[0m [1;32mimport[0m [0mtoeplitz[0m[1;33m[0m[1;33m[0m[0m
[0;32m      3[0m [1;32mimport[0m [0mnumpy[0m [1;32mas[0m [0mnp[0m[1;33m[0m[1;33m[0m[0m
[0;32m      4[0m [1;33m[0m[0m
[0;32m      5[0m [0macov1[0m [1;33m=[0m [0marma_acovf[0m[1;33m([0m[0mar[0m[1;33m=[0m[1;33m[[0m[1;36m1[0m[1;33m,[0m [1;33m-[0m[1;36m.4[0m[1;33m][0m[1;33m,[0m [0mma[0m[1;33m=[0m[1;33m[[0m[1;36m1[0m[1;33m][0m[1;33m,[0m [0mnobs[0m[1;33m=[0m[1;36m10[0m[1;33m,[0m [0msigma2[0m[1;33m=[0m[1;36m1[0m[1;33m)[0m[1;33m[0m[1;33m[0m[0m

[1;31mModuleNotFoundError[0m: No module named 'statsmodels'
ModuleNotFoundError: No module named 'statsmodels'

