Traceback (most recent call last):
  File "C:\Users\eeu227\AppData\Local\Continuum\anaconda3\envs\jbook_env\lib\site-packages\jupyter_cache\executors\utils.py", line 56, in single_nb_execution
    record_timing=False,
  File "C:\Users\eeu227\AppData\Local\Continuum\anaconda3\envs\jbook_env\lib\site-packages\nbclient\client.py", line 1093, in execute
    return NotebookClient(nb=nb, resources=resources, km=km, **kwargs).execute()
  File "C:\Users\eeu227\AppData\Local\Continuum\anaconda3\envs\jbook_env\lib\site-packages\nbclient\util.py", line 84, in wrapped
    return just_run(coro(*args, **kwargs))
  File "C:\Users\eeu227\AppData\Local\Continuum\anaconda3\envs\jbook_env\lib\site-packages\nbclient\util.py", line 62, in just_run
    return loop.run_until_complete(coro)
  File "C:\Users\eeu227\AppData\Local\Continuum\anaconda3\envs\jbook_env\lib\asyncio\base_events.py", line 587, in run_until_complete
    return future.result()
  File "C:\Users\eeu227\AppData\Local\Continuum\anaconda3\envs\jbook_env\lib\site-packages\nbclient\client.py", line 560, in async_execute
    cell, index, execution_count=self.code_cells_executed + 1
  File "C:\Users\eeu227\AppData\Local\Continuum\anaconda3\envs\jbook_env\lib\site-packages\nbclient\client.py", line 854, in async_execute_cell
    self._check_raise_for_error(cell, exec_reply)
  File "C:\Users\eeu227\AppData\Local\Continuum\anaconda3\envs\jbook_env\lib\site-packages\nbclient\client.py", line 756, in _check_raise_for_error
    raise CellExecutionError.from_cell_and_msg(cell, exec_reply_content)
nbclient.exceptions.CellExecutionError: An error occurred while executing the following cell:
------------------
import matplotlib.pyplot as plt
import pandas as pd
from fredapi import Fred
fred = Fred(api_key="your_api_key")

start = '1948-01'
end = '2022-01'

unr = fred.get_series('UNRATE',  observation_start=start)
unr.index.freq = unr.index.inferred_freq
unr.name = 'Unemployment'
recessions = fred.get_series('USREC',  observation_start=start, observation_end=end)
recessions.name='recessions'
df = pd.merge(unr, recessions, how='outer', left_index=True, right_index=True)
df = df.fillna(value=0)
df.index.freq = df.index.inferred_freq
dates = df.index._mpl_repr()


indpr = fred.get_series('INDPRO',  observation_start=start, observation_end=end)
indpr.index.freq = indpr.index.inferred_freq
indpr.name = 'Industrial production'
indpr = indpr.to_frame()
------------------

[1;31m---------------------------------------------------------------------------[0m
[1;31mModuleNotFoundError[0m                       Traceback (most recent call last)
[1;32mC:\Users\eeu227\AppData\Local\Temp/ipykernel_11924/28448573.py[0m in [0;36m<module>[1;34m[0m
[1;32m----> 1[1;33m [1;32mimport[0m [0mmatplotlib[0m[1;33m.[0m[0mpyplot[0m [1;32mas[0m [0mplt[0m[1;33m[0m[1;33m[0m[0m
[0m[0;32m      2[0m [1;32mimport[0m [0mpandas[0m [1;32mas[0m [0mpd[0m[1;33m[0m[1;33m[0m[0m
[0;32m      3[0m [1;32mfrom[0m [0mfredapi[0m [1;32mimport[0m [0mFred[0m[1;33m[0m[1;33m[0m[0m
[0;32m      4[0m [0mfred[0m [1;33m=[0m [0mFred[0m[1;33m([0m[0mapi_key[0m[1;33m=[0m[1;34m"your_api_key"[0m[1;33m)[0m[1;33m[0m[1;33m[0m[0m
[0;32m      5[0m [1;33m[0m[0m

[1;31mModuleNotFoundError[0m: No module named 'matplotlib'
ModuleNotFoundError: No module named 'matplotlib'

